Workbook

Sheet peakflow_q1_2025_dirty
A1: DealID | B1: Date | C1: CustomerName | D1: CategoryName | E1: SalesRep | F1: Manager | G1: Region | H1: Units | I1: UnitPrice | J1: Revenue
A2: D-1088 | B2: 45658 | C2: Helix Systems | D2: Starter Plan | E2: Nina Petrov | F2: Lukas Becker | G2: North America | H2: 2 | I2: 44.27 | J2: 88.54
A3: D-1108 | B3: 45658 | C3: Meridian Group | D3: Pro Plan | E3: Tom Wilson | F3: Lukas Becker | G3: North America | H3: 10 | I3: 224.49 | J3: 125889
A4: D-1230 | B4: 45658 | C4: Fusion Group | D4: Pro Plan | E4: Marcus Johnson | F4: Sarah Chen | G4: LATAM | H4: 2 | I4: 248.58 | J4: $497.16
A5: D-1035 | B5: 45659 | C5: Nova Inc | D5: Add-on: Support | E5: Elena Rossi | F5: Lukas Becker | G5: EMEA | H5: 1 | I5: 112.19 | J5: 112.19
A6: D-1152 | B6: 45659 | C6: Catalyst Inc | D6: Starter Plan | E6: Elena Rossi | F6: Lukas Becker | G6: North America | H6: 1 | I6: 73.94 | J6: 73.94
A7: D-1202 | B7: 45659 | C7: Nimbus Co | D7: Business Plan | E7: James Park | F7: Owen Walsh | G7: North America | H7: 5 | I7: 369.19 | J7: 1845.95
A8: D-1249 | B8: 45659 | C8: Summit Group | D8: Enterprise Plan | E8: Elena Rossi | F8: Lukas Becker | G8: North America | H8: 1 | I8: 1198.59 | J8: 1198.59
A9: D-1054 | B9: 45661 | C9: Northwind Co | D9: Enterprise Plan | E9: David Kim | F9: Sarah Chen | G9: EMEA | H9: 2 | I9: 1182.78 | J9: 2365.56
A10: D-1102 | B10: 45661 | C10: Lumen Labs | D10: Starter Plan | E10: Carlos Mendez | F10: Maya Rodriguez | G10: EMEA | H10: 1 | I10: 68.06 | J10: 68.06
A11: D-1115 | B11: 45661 | C11: Kestrel Co | D11: Add-on: Support | E11: Tom Wilson | F11: Lukas Becker | G11: APAC | H11: 2 | I11: 118.97 | J11: 237.94
A12: D-1138 | B12: 45661 | C12: Nova Inc | D12: Starter Plan | E12: Marcus Johnson | F12: Sarah Chen | G12: LATAM | H12: 5 | I12: 53.28 | J12: 266.4
A13: D-1231 | B13: 45661 | C13: Borealis Co | D13: Enterprise Plan | E13: Marcus Johnson | F13: Sarah Chen | G13: EMEA | H13: 1 | I13: 992.76 | J13: 992.76
A14: D-1008 | B14: 45662 | C14: Phoenix Co | D14: Pro Plan | E14: Tom Wilson | F14: Lukas Becker | G14: latam | H14: 20 | I14: 249.04 | J14: 1125162
A15: D-1071 | B15: 45662 | C15: Apex Group | D15: Business Plan | E15: David Kim | F15: Sarah Chen | G15: apac | H15: 1 | I15: 386.52 | J15: 386.52
A16: D-1105 | B16: 45662 | C16: Kestrel Co | D16: Pro Plan | E16: Elena Rossi | F16: Lukas Becker | G16: North America | H16: 1 | I16: 226.12 | J16: $226.12
A17: D-1110 | B17: 45662 | C17: Rivet Co | D17: Starter Plan | E17: James Park | F17: Owen Walsh | G17: latam | H17: 1 | I17: 73.28 | J17: 73.28
A18: D-1112 | B18: 45662 | C18: Borealis Co | D18: Starter Plan | E18: Hannah Lee | F18: Owen Walsh | G18: EMEA | H18: 5 | I18: 45.99 | J18: $229.95
A19: D-1132 | B19: 45662 | C19: Quanta Labs | D19: Starter Plan | E19: Hannah Lee | F19: Owen Walsh | G19: APAC | H19: 50 | I19: 70.68 | J19: $3,534.00
A20: D-1150 | B20: 45662 | C20: Nimbus Co | D20: Pro Plan | E20: James Park | F20: Owen Walsh | G20: EMEA | H20: 20 | I20: 192.21 | J20: 710064
A21: D-1194 | B21: 45662 | C21: Onyx Group | D21: Pro Plan | E21: Sophie Laurent | F21: Maya Rodriguez | G21: North America | H21: 2 | I21: 193.5 | J21: $387.00
A22: D-1091 | B22: 45663 | C22: Fusion Group | D22: Starter Plan | E22: Marcus Johnson | F22: Sarah Chen | G22: APAC | H22: 1 | I22: 53.39 | J22: $53.39
A23: D-1092 | B23: 45663 | C23: Summit Group | D23: Pro Plan | E23: Carlos Mendez | F23: Maya Rodriguez | G23: APAC | H23: 1 | I23: 202.22 | J23: 202.22
A24: D-1211 | B24: 45663 | C24: Apex Group | D24: Add-on: Analytics | E24: James Park | F24: Owen Walsh | G24: LATAM | H24: 5 | I24: 69.69 | J24: $348.45
A25: D-1063 | B25: 45664 | C25: Granite Co | D25: Add-on: Support | E25: Marcus Johnson | F25: Sarah Chen | G25: North America | H25: 1 | I25: 93.27 | J25: 93.27
A26: D-1206 | B26: 45664 | C26: Stellar Co | D26: Add-on: Analytics | E26: Elena Rossi | F26: Lukas Becker | G26: APAC | H26: 5 | I26: 74.69 | J26: 373.45
A27: D-1123 | B27: 45665 | C27: Nimbus Co | D27: Add-on: Support | E27: Tom Wilson | F27: Lukas Becker | G27: latam | H27: 1 | I27: 92.92 | J27: 92.92
A28: D-1121 | B28: 45666 | C28: Nova Inc | D28: Enterprise Plan | E28: Priya Patel | F28: Maya Rodriguez | G28: apac | H28: 1 | I28: 1388.69 | J28: $1,388.69
A29: D-1029 | B29: 45667 | C29: Cascade Group | D29: Starter Plan | E29: Sophie Laurent | F29: Maya Rodriguez | G29: APAC | H29: 50 | I29: 72.26 | J29: 3613.0
A30: D-1141 | B30: 45667 | C30: Nova Inc | D30: Enterprise Plan | E30: Elena Rossi | F30: Lukas Becker | G30: apac | H30: 1 | I30: 1234.13 | J30: $1234.13
A31: D-1155 | B31: 45667 | C31: Juniper Group | D31: Pro Plan | E31: Nina Petrov | F31: Lukas Becker | G31: North America | H31: 1 | I31: 219.47 | J31: 219.47
A32: D-1209 | B32: 45667 | C32: Lattice Co | D32: Pro Plan | E32: Elena Rossi | F32: Lukas Becker | G32: North America | H32: 1 | I32: 276.18 | J32: $276.18
... A42: D-1220 | B42: 45669 | C42: Echo Labs | D42: Add-on: Analytics | E42: Marcus Johnson | F42: Sarah Chen | G42: North America | H42: 1 | I42: 92.43 | J42: 92.43
A43: D-1058 | B43: 45670 | C43: Nimbus Co | D43: Business Plan | E43: Marcus Johnson | F43: Sarah Chen | G43: APAC | H43: 5 | I43: 422.7 | J43: 77919
A44: D-1229 | B44: 45670 | C44: Arcadia Inc | D44: Business Plan | E44: David Kim | F44: Sarah Chen | G44: EMEA | H44: 2 | I44: 409.02 | J44: 818.04
A45: D-1245 | B45: 45670 | C45: Quill Labs | D45: Pro Plan | E45: Priya Patel | F45: Maya Rodriguez | G45: North America | H45: 5 | I45: 177.21 | J45: $886.05
A46: D-1075 | B46: 45671 | C46: Beacon Labs | D46: Pro Plan | E46: Carlos Mendez | F46: Maya Rodriguez | G46: APAC | H46: 5 | I46: 230.19 | J46: $1,150.95
A47: D-1079 | B47: 45671 | C47: Onyx Group | D47: Starter Plan | E47: Nina Petrov | F47: Lukas Becker | G47: North America | H47: 1 | I47: 66.71 | J47: 66.71
A48: D-1169 | B48: 45671 | C48: Quartz Co | D48: Business Plan | E48: David Kim | F48: Sarah Chen | G48: EMEA | H48: 1 | I48: 426.07 | J48: $426.07
A49: D-1234 | B49: 45671 | C49: Pacific Co | D49: Pro Plan | E49: Priya Patel | F49: Maya Rodriguez | G49: North America | H49: 2 | I49: 233.74 | J49: $467.48
...

Sheet Datensätze
A1: DealID | B1: Date | C1: CustomerName | D1: CategoryName | E1: SalesRep | F1: Manager | G1: Region | H1: Units | I1: UnitPrice | J1: Revenue | K1: CategoryName gesäubert | L1: SalesRep gesäubert | M1: Regiongesäubert | N1: UnitPrice gesäubert | O1: Revenuegesäubert
A2: D-1001 | B2: 45669 | C2: Phoenix Co | D2: Starter Plan | E2: Priya Patel | F2: Maya Rodriguez | G2: LATAM | H2: 1 | I2: 45.33 | J2: 45.33 | K2: {=IF(D2:D998="","",SUBSTITUTE(PROPER(D2:D998),"Add-On","Add-on"))} -> Starter Plan | L2: =TRIM(E2) -> Priya Patel | M2: =IF(G2="","",IF(LOWER(TRIM(G2))="north america","North America",IF(LOWER(TRIM(G2))="emea","EMEA",IF(LOWER(TRIM(G2))="apac","APAC",IF(LOWER(TRIM(G2))="latam","LATAM",TRIM(G2)))))) -> LATAM | N2: =VALUE(SUBSTITUTE(SUBSTITUTE(SUBSTITUTE(I2,"$",""),",",""),".",",")) -> 45.33 | O2: =IF(OR(H2="",N2=""),"",H2*N2) -> 45.33
A3: D-1002 | B3: 45683 | C3: Nova Inc | D3: Pro Plan | E3: David Kim | F3: Sarah Chen | G3: latam | H3: 1 | I3: 243.59 | J3: 243.59 | K3: Pro Plan | L3: =TRIM(E3) -> David Kim | M3: =IF(G3="","",IF(LOWER(TRIM(G3))="north america","North America",IF(LOWER(TRIM(G3))="emea","EMEA",IF(LOWER(TRIM(G3))="apac","APAC",IF(LOWER(TRIM(G3))="latam","LATAM",TRIM(G3)))))) -> LATAM | N3: =VALUE(SUBSTITUTE(SUBSTITUTE(SUBSTITUTE(I3,"$",""),",",""),".",",")) -> 243.59 | O3: =IF(OR(H3="",N3=""),"",H3*N3) -> 243.59
A4: D-1003 | B4: 45685 | C4: Citadel Group | D4: Enterprise Plan | E4: Carlos Mendez | F4: Maya Rodriguez | G4: EMEA | H4: 10 | I4: 1330.75 | J4: 13307.5 | K4: Enterprise Plan | L4: =TRIM(E4) -> Carlos Mendez | M4: =IF(G4="","",IF(LOWER(TRIM(G4))="north america","North America",IF(LOWER(TRIM(G4))="emea","EMEA",IF(LOWER(TRIM(G4))="apac","APAC",IF(LOWER(TRIM(G4))="latam","LATAM",TRIM(G4)))))) -> EMEA | N4: =VALUE(SUBSTITUTE(SUBSTITUTE(SUBSTITUTE(I4,"$",""),",",""),".",",")) -> 1330.75 | O4: =IF(OR(H4="",N4=""),"",H4*N4) -> 13307.5 | Q4: Protokoll 2 Zeilen manuell gelöscht (D-TEST1, D-TEST2) Kategorienamen korrigieren und vereinheitlich Leerzeichen in der Spalte Vertriebsmitarbeiter (SalesRep) entfernt In der Spalte Region Groß-/Kleinschreibung vereinheitlicht UnitPrice & Revenue als Zahl dargestellt
A5: D-1004 | B5: 45725 | C5: Prism Group | D5: Business Plan | E5: Aisha Hassan | F5: Sarah Chen | G5: LATAM | H5: 1 | I5: 492.03 | J5: $492.03 | K5: Business Plan | L5: =TRIM(E5) -> Aisha Hassan | M5: =IF(G5="","",IF(LOWER(TRIM(G5))="north america","North America",IF(LOWER(TRIM(G5))="emea","EMEA",IF(LOWER(TRIM(G5))="apac","APAC",IF(LOWER(TRIM(G5))="latam","LATAM",TRIM(G5)))))) -> LATAM | N5: =VALUE(SUBSTITUTE(SUBSTITUTE(SUBSTITUTE(I5,"$",""),",",""),".",",")) -> 492.03 | O5: =IF(OR(H5="",N5=""),"",H5*N5) -> 492.03
A6: D-1005 | B6: 45712 | C6: Echo Labs | D6: Pro Plan | E6: Elena Rossi | F6: Lukas Becker | G6: North America | H6: 1 | I6: 233.69 | J6: 233.69 | K6: Pro Plan | L6: =TRIM(E6) -> Elena Rossi | M6: =IF(G6="","",IF(LOWER(TRIM(G6))="north america","North America",IF(LOWER(TRIM(G6))="emea","EMEA",IF(LOWER(TRIM(G6))="apac","APAC",IF(LOWER(TRIM(G6))="latam","LATAM",TRIM(G6)))))) -> North America | N6: =VALUE(SUBSTITUTE(SUBSTITUTE(SUBSTITUTE(I6,"$",""),",",""),".",",")) -> 233.69 | O6: =IF(OR(H6="",N6=""),"",H6*N6) -> 233.69
A7: D-1006 | B7: 45683 | C7: Nova Inc | D7: Add-on: Support | E7: Aisha Hassan | F7: Sarah Chen | G7: APAC | H7: 1 | I7: 116.31 | J7: $116.31 | K7: Add-on: Support | L7: =TRIM(E7) -> Aisha Hassan | M7: =IF(G7="","",IF(LOWER(TRIM(G7))="north america","North America",IF(LOWER(TRIM(G7))="emea","EMEA",IF(LOWER(TRIM(G7))="apac","APAC",IF(LOWER(TRIM(G7))="latam","LATAM",TRIM(G7)))))) -> APAC | N7: =VALUE(SUBSTITUTE(SUBSTITUTE(SUBSTITUTE(I7,"$",""),",",""),".",",")) -> 116.31 | O7: =IF(OR(H7="",N7=""),"",H7*N7) -> 116.31
A8: D-1007 | B8: 45678 | C8: Borealis Co | D8: Add-on: Support | E8: Nina Petrov | F8: Lukas Becker | G8: LATAM | H8: 1 | I8: 146.67 | J8: 146.67 | K8: Add-on: Support | L8: =TRIM(E8) -> Nina Petrov | M8: =IF(G8="","",IF(LOWER(TRIM(G8))="north america","North America",IF(LOWER(TRIM(G8))="emea","EMEA",IF(LOWER(TRIM(G8))="apac","APAC",IF(LOWER(TRIM(G8))="latam","LATAM",TRIM(G8)))))) -> LATAM | N8: =VALUE(SUBSTITUTE(SUBSTITUTE(SUBSTITUTE(I8,"$",""),",",""),".",",")) -> 146.67 | O8: =IF(OR(H8="",N8=""),"",H8*N8) -> 146.67
A9: D-1008 | B9: 45662 | C9: Phoenix Co | D9: Pro Plan | E9: Tom Wilson | F9: Lukas Becker | G9: latam | H9: 20 | I9: 249.04 | J9: 1125162 | K9: Pro Plan | L9: =TRIM(E9) -> Tom Wilson | M9: =IF(G9="","",IF(LOWER(TRIM(G9))="north america","North America",IF(LOWER(TRIM(G9))="emea","EMEA",IF(LOWER(TRIM(G9))="apac","APAC",IF(LOWER(TRIM(G9))="latam","LATAM",TRIM(G9)))))) -> LATAM | N9: =VALUE(SUBSTITUTE(SUBSTITUTE(SUBSTITUTE(I9,"$",""),",",""),".",",")) -> 249.04 | O9: =IF(OR(H9="",N9=""),"",H9*N9) -> 4980.8
A10: D-1009 | B10: 45669 | C10: Foundry Group | D10: Pro Plan | E10: Marcus Johnson | F10: Sarah Chen | G10: North America | H10: 1 | I10: 213.81 | J10: 213.81 | K10: Pro Plan | L10: =TRIM(E10) -> Marcus Johnson | M10: =IF(G10="","",IF(LOWER(TRIM(G10))="north america","North America",IF(LOWER(TRIM(G10))="emea","EMEA",IF(LOWER(TRIM(G10))="apac","APAC",IF(LOWER(TRIM(G10))="latam","LATAM",TRIM(G10)))))) -> North America | N10: =VALUE(SUBSTITUTE(SUBSTITUTE(SUBSTITUTE(I10,"$",""),",",""),".",",")) -> 213.81 | O10: =IF(OR(H10="",N10=""),"",H10*N10) -> 213.81
A11: D-1010 | B11: 45683 | C11: Driftwood Co | D11: Business Plan | E11: Marcus Johnson | F11: Sarah Chen | G11: APAC | H11: 1 | I11: 428.51 | J11: 428.51 | K11: Business Plan | L11: =TRIM(E11) -> Marcus Johnson | M11: =IF(G11="","",IF(LOWER(TRIM(G11))="north america","North America",IF(LOWER(TRIM(G11))="emea","EMEA",IF(LOWER(TRIM(G11))="apac","APAC",IF(LOWER(TRIM(G11))="latam","LATAM",TRIM(G11)))))) -> APAC | N11: =VALUE(SUBSTITUTE(SUBSTITUTE(SUBSTITUTE(I11,"$",""),",",""),".",",")) -> 428.51 | O11: =IF(OR(H11="",N11=""),"",H11*N11) -> 428.51
A12: D-1011 | B12: 45674 | C12: Harbor Inc | D12: Business Plan | E12: James Park | F12: Owen Walsh | G12: North America | H12: 1 | I12: 410.61 | J12: 410.61 | K12: Business Plan | L12: =TRIM(E12) -> James Park | M12: =IF(G12="","",IF(LOWER(TRIM(G12))="north america","North America",IF(LOWER(TRIM(G12))="emea","EMEA",IF(LOWER(TRIM(G12))="apac","APAC",IF(LOWER(TRIM(G12))="latam","LATAM",TRIM(G12)))))) -> North America | N12: =VALUE(SUBSTITUTE(SUBSTITUTE(SUBSTITUTE(I12,"$",""),",",""),".",",")) -> 410.61 | O12: =IF(OR(H12="",N12=""),"",H12*N12) -> 410.61
A13: D-1012 | B13: 45677 | C13: Lumen Labs | D13: Add-on: Analytics | E13: Priya Patel | F13: Maya Rodriguez | G13: LATAM | H13: 5 | I13: 103.1 | J13: 515.5 | K13: Add-on: Analytics | L13: =TRIM(E13) -> Priya Patel | M13: =IF(G13="","",IF(LOWER(TRIM(G13))="north america","North America",IF(LOWER(TRIM(G13))="emea","EMEA",IF(LOWER(TRIM(G13))="apac","APAC",IF(LOWER(TRIM(G13))="latam","LATAM",TRIM(G13)))))) -> LATAM | N13: =VALUE(SUBSTITUTE(SUBSTITUTE(SUBSTITUTE(I13,"$",""),",",""),".",",")) -> 103.1 | O13: =IF(OR(H13="",N13=""),"",H13*N13) -> 515.5
A14: D-1013 | B14: 45680 | C14: Apex Group | D14: Starter Plan | E14: Nina Petrov | F14: Lukas Becker | G14: LATAM | H14: 1 | I14: 46.97 | J14: 46.97 | K14: Starter Plan | L14: =TRIM(E14) -> Nina Petrov | M14: =IF(G14="","",IF(LOWER(TRIM(G14))="north america","North America",IF(LOWER(TRIM(G14))="emea","EMEA",IF(LOWER(TRIM(G14))="apac","APAC",IF(LOWER(TRIM(G14))="latam","LATAM",TRIM(G14)))))) -> LATAM | N14: =VALUE(SUBSTITUTE(SUBSTITUTE(SUBSTITUTE(I14,"$",""),",",""),".",",")) -> 46.97 | O14: =IF(OR(H14="",N14=""),"",H14*N14) -> 46.97
A15: D-1014 | B15: 45687 | C15: Obsidian Co | D15: Add-on: Support | E15: Carlos Mendez | F15: Maya Rodriguez | G15: emea | H15: 1 | I15: 114.94 | J15: $114.94 | K15: Add-on: Support | L15: =TRIM(E15) -> Carlos Mendez | M15: =IF(G15="","",IF(LOWER(TRIM(G15))="north america","North America",IF(LOWER(TRIM(G15))="emea","EMEA",IF(LOWER(TRIM(G15))="apac","APAC",IF(LOWER(TRIM(G15))="latam","LATAM",TRIM(G15)))))) -> EMEA | N15: =VALUE(SUBSTITUTE(SUBSTITUTE(SUBSTITUTE(I15,"$",""),",",""),".",",")) -> 114.94 | O15: =IF(OR(H15="",N15=""),"",H15*N15) -> 114.94
A16: D-1015 | B16: 45694 | C16: Citadel Group | D16: Starter Plan | E16: Raj Sharma | F16: Owen Walsh | G16: APAC | H16: 1 | I16: 42.9 | J16: 42.9 | K16: Starter Plan | L16: =TRIM(E16) -> Raj Sharma | M16: =IF(G16="","",IF(LOWER(TRIM(G16))="north america","North America",IF(LOWER(TRIM(G16))="emea","EMEA",IF(LOWER(TRIM(G16))="apac","APAC",IF(LOWER(TRIM(G16))="latam","LATAM",TRIM(G16)))))) -> APAC | N16: =VALUE(SUBSTITUTE(SUBSTITUTE(SUBSTITUTE(I16,"$",""),",",""),".",",")) -> 42.9 | O16: =IF(OR(H16="",N16=""),"",H16*N16) -> 42.9
A17: D-1016 | B17: 45709 | C17: Driftwood Co | D17: Pro Plan | E17: Marcus Johnson | F17: Sarah Chen | G17: North America | H17: 2 | I17: 273.36 | J17: 546.72 | K17: Pro Plan | L17: =TRIM(E17) -> Marcus Johnson | M17: =IF(G17="","",IF(LOWER(TRIM(G17))="north america","North America",IF(LOWER(TRIM(G17))="emea","EMEA",IF(LOWER(TRIM(G17))="apac","APAC",IF(LOWER(TRIM(G17))="latam","LATAM",TRIM(G17)))))) -> North America | N17: =VALUE(SUBSTITUTE(SUBSTITUTE(SUBSTITUTE(I17,"$",""),",",""),".",",")) -> 273.36 | O17: =IF(OR(H17="",N17=""),"",H17*N17) -> 546.72
A18: D-1017 | B18: 45705 | C18: Nova Inc | D18: Enterprise Plan | E18: Priya Patel | F18: Maya Rodriguez | G18: LATAM | H18: 1 | I18: 1339.78 | J18: 1339.78 | K18: Enterprise Plan | L18: =TRIM(E18) -> Priya Patel | M18: =IF(G18="","",IF(LOWER(TRIM(G18))="north america","North America",IF(LOWER(TRIM(G18))="emea","EMEA",IF(LOWER(TRIM(G18))="apac","APAC",IF(LOWER(TRIM(G18))="latam","LATAM",TRIM(G18)))))) -> LATAM | N18: =VALUE(SUBSTITUTE(SUBSTITUTE(SUBSTITUTE(I18,"$",""),",",""),".",",")) -> 1339.78 | O18: =IF(OR(H18="",N18=""),"",H18*N18) -> 1339.78
A19: D-1018 | B19: 45741 | C19: Nimbus Co | D19: Enterprise Plan | E19: Tom Wilson | F19: Lukas Becker | G19: latam | H19: 1 | I19: 1227.17 | J19: $1227.17 | K19: Enterprise Plan | L19: =TRIM(E19) -> Tom Wilson | M19: =IF(G19="","",IF(LOWER(TRIM(G19))="north america","North America",IF(LOWER(TRIM(G19))="emea","EMEA",IF(LOWER(TRIM(G19))="apac","APAC",IF(LOWER(TRIM(G19))="latam","LATAM",TRIM(G19)))))) -> LATAM | N19: =VALUE(SUBSTITUTE(SUBSTITUTE(SUBSTITUTE(I19,"$",""),",",""),".",",")) -> 1227.17 | O19: =IF(OR(H19="",N19=""),"",H19*N19) -> 1227.17
A20: D-1019 | B20: 45744 | C20: Onyx Group | D20: Starter Plan | E20: Tom Wilson | F20: Lukas Becker | G20: APAC | H20: 1 | I20: 72.37 | J20: 72.37 | K20: Starter Plan | L20: =TRIM(E20) -> Tom Wilson | M20: =IF(G20="","",IF(LOWER(TRIM(G20))="north america","North America",IF(LOWER(TRIM(G20))="emea","EMEA",IF(LOWER(TRIM(G20))="apac","APAC",IF(LOWER(TRIM(G20))="latam","LATAM",TRIM(G20)))))) -> APAC | N20: =VALUE(SUBSTITUTE(SUBSTITUTE(SUBSTITUTE(I20,"$",""),",",""),".",",")) -> 72.37 | O20: =IF(OR(H20="",N20=""),"",H20*N20) -> 72.37
A21: D-1020 | B21: 45714 | C21: Harbor Inc | D21: Pro Plan | E21: Tom Wilson | F21: Lukas Becker | G21: EMEA | H21: 10 | I21: 162.02 | J21: 1620.2 | K21: Pro Plan | L21: =TRIM(E21) -> Tom Wilson | M21: =IF(G21="","",IF(LOWER(TRIM(G21))="north america","North America",IF(LOWER(TRIM(G21))="emea","EMEA",IF(LOWER(TRIM(G21))="apac","APAC",IF(LOWER(TRIM(G21))="latam","LATAM",TRIM(G21)))))) -> EMEA | N21: =VALUE(SUBSTITUTE(SUBSTITUTE(SUBSTITUTE(I21,"$",""),",",""),".",",")) -> 162.02 | O21: =IF(OR(H21="",N21=""),"",H21*N21) -> 1620.2
... A47: D-1046 | B47: 45735 | C47: Beacon Labs | D47: Enterprise Plan | E47: James Park | F47: Owen Walsh | G47: North America | H47: 2 | I47: 1266.5 | J47: 2533.0 | K47: Enterprise Plan | L47: =TRIM(E47) -> James Park | M47: =IF(G47="","",IF(LOWER(TRIM(G47))="north america","North America",IF(LOWER(TRIM(G47))="emea","EMEA",IF(LOWER(TRIM(G47))="apac","APAC",IF(LOWER(TRIM(G47))="latam","LATAM",TRIM(G47)))))) -> North America | N47: =VALUE(SUBSTITUTE(SUBSTITUTE(SUBSTITUTE(I47,"$",""),",",""),".",",")) -> 1266.5 | O47: =IF(OR(H47="",N47=""),"",H47*N47) -> 2533
A48: D-1047 | B48: 45714 | C48: Atlas Group | D48: Starter plan | E48: James Park | F48: Owen Walsh | G48: north america | H48: 20 | I48: 110.31 | J48: 111797 | K48: Starter Plan | L48: =TRIM(E48) -> James Park | M48: =IF(G48="","",IF(LOWER(TRIM(G48))="north america","North America",IF(LOWER(TRIM(G48))="emea","EMEA",IF(LOWER(TRIM(G48))="apac","APAC",IF(LOWER(TRIM(G48))="latam","LATAM",TRIM(G48)))))) -> North America | N48: =VALUE(SUBSTITUTE(SUBSTITUTE(SUBSTITUTE(I48,"$",""),",",""),".",",")) -> 110.31 | O48: =IF(OR(H48="",N48=""),"",H48*N48) -> 2206.2
A49: D-1048 | B49: 45678 | C49: Orbit Co | D49: Pro Plan | E49: Priya Patel | F49: Maya Rodriguez | G49: APAC | H49: 2 | I49: 153.06 | J49: 306.12 | K49: Pro Plan | L49: =TRIM(E49) -> Priya Patel | M49: =IF(G49="","",IF(LOWER(TRIM(G49))="north america","North America",IF(LOWER(TRIM(G49))="emea","EMEA",IF(LOWER(TRIM(G49))="apac","APAC",IF(LOWER(TRIM(G49))="latam","LATAM",TRIM(G49)))))) -> APAC | N49: =VALUE(SUBSTITUTE(SUBSTITUTE(SUBSTITUTE(I49,"$",""),",",""),".",",")) -> 153.06 | O49: =IF(OR(H49="",N49=""),"",H49*N49) -> 306.12
A50: D-1049 | B50: 45712 | C50: Obsidian Co | D50: Add-on: Analytics | E50: Marcus Johnson | F50: Sarah Chen | G50: North America | H50: 1 | I50: 67.42 | J50: 67.42 | K50: Add-on: Analytics | L50: =TRIM(E50) -> Marcus Johnson | M50: =IF(G50="","",IF(LOWER(TRIM(G50))="north america","North America",IF(LOWER(TRIM(G50))="emea","EMEA",IF(LOWER(TRIM(G50))="apac","APAC",IF(LOWER(TRIM(G50))="latam","LATAM",TRIM(G50)))))) -> North America | N50: =VALUE(SUBSTITUTE(SUBSTITUTE(SUBSTITUTE(I50,"$",""),",",""),".",",")) -> 67.42 | O50: =IF(OR(H50="",N50=""),"",H50*N50) -> 67.42
A51: D-1050 | B51: 45700 | C51: Atlas Group | D51: Starter Plan | E51: Hannah Lee | F51: Owen Walsh | G51: North America | H51: 5 | I51: 52.69 | J51: 263.45 | K51: Starter Plan | L51: =TRIM(E51) -> Hannah Lee | M51: =IF(G51="","",IF(LOWER(TRIM(G51))="north america","North America",IF(LOWER(TRIM(G51))="emea","EMEA",IF(LOWER(TRIM(G51))="apac","APAC",IF(LOWER(TRIM(G51))="latam","LATAM",TRIM(G51)))))) -> North America | N51: =VALUE(SUBSTITUTE(SUBSTITUTE(SUBSTITUTE(I51,"$",""),",",""),".",",")) -> 52.69 | O51: =IF(OR(H51="",N51=""),"",H51*N51) -> 263.45
A52: D-1051 | B52: 45687 | C52: Orbit Co | D52: Enterprise Plan | E52: Elena Rossi | F52: Lukas Becker | G52: APAC | H52: 2 | I52: 1035.34 | J52: 2070.68 | K52: Enterprise Plan | L52: =TRIM(E52) -> Elena Rossi | M52: =IF(G52="","",IF(LOWER(TRIM(G52))="north america","North America",IF(LOWER(TRIM(G52))="emea","EMEA",IF(LOWER(TRIM(G52))="apac","APAC",IF(LOWER(TRIM(G52))="latam","LATAM",TRIM(G52)))))) -> APAC | N52: =VALUE(SUBSTITUTE(SUBSTITUTE(SUBSTITUTE(I52,"$",""),",",""),".",",")) -> 1035.34 | O52: =IF(OR(H52="",N52=""),"",H52*N52) -> 2070.68
A53: D-1052 | B53: 45709 | C53: Cascade Group | D53: Business Plan | E53: Sophie Laurent | F53: Maya Rodriguez | G53: EMEA | H53: 10 | I53: 490.82 | J53: 1098682 | K53: Business Plan | L53: =TRIM(E53) -> Sophie Laurent | M53: =IF(G53="","",IF(LOWER(TRIM(G53))="north america","North America",IF(LOWER(TRIM(G53))="emea","EMEA",IF(LOWER(TRIM(G53))="apac","APAC",IF(LOWER(TRIM(G53))="latam","LATAM",TRIM(G53)))))) -> EMEA | N53: =VALUE(SUBSTITUTE(SUBSTITUTE(SUBSTITUTE(I53,"$",""),",",""),".",",")) -> 490.82 | O53: =IF(OR(H53="",N53=""),"",H53*N53) -> 4908.2
A54: D-1053 | B54: 45740 | C54: Foundry Group | D54: Starter Plan | E54: Carlos Mendez | F54: Maya Rodriguez | G54: EMEA | H54: 50 | I54: 48.49 | J54: $2424.5 | K54: Starter Plan | L54: =TRIM(E54) -> Carlos Mendez | M54: =IF(G54="","",IF(LOWER(TRIM(G54))="north america","North America",IF(LOWER(TRIM(G54))="emea","EMEA",IF(LOWER(TRIM(G54))="apac","APAC",IF(LOWER(TRIM(G54))="latam","LATAM",TRIM(G54)))))) -> EMEA | N54: =VALUE(SUBSTITUTE(SUBSTITUTE(SUBSTITUTE(I54,"$",""),",",""),".",",")) -> 48.49 | O54: =IF(OR(H54="",N54=""),"",H54*N54) -> 2424.5
A55: D-1054 | B55: 45661 | C55: Northwind Co | D55: Enterprise Plan | E55: David Kim | F55: Sarah Chen | G55: EMEA | H55: 2 | I55: 1182.78 | J55: 2365.56 | K55: Enterprise Plan | L55: =TRIM(E55) -> David Kim | M55: =IF(G55="","",IF(LOWER(TRIM(G55))="north america","North America",IF(LOWER(TRIM(G55))="emea","EMEA",IF(LOWER(TRIM(G55))="apac","APAC",IF(LOWER(TRIM(G55))="latam","LATAM",TRIM(G55)))))) -> EMEA | N55: =VALUE(SUBSTITUTE(SUBSTITUTE(SUBSTITUTE(I55,"$",""),",",""),".",",")) -> 1182.78 | O55: =IF(OR(H55="",N55=""),"",H55*N55) -> 2365.56
A56: D-1055 | B56: 45690 | C56: Phoenix Co | D56: Starter Plan | E56: Raj Sharma | F56: Owen Walsh | G56: EMEA | H56: 5 | I56: 42.45 | J56: 212.25 | K56: Starter Plan | L56: =TRIM(E56) -> Raj Sharma | M56: =IF(G56="","",IF(LOWER(TRIM(G56))="north america","North America",IF(LOWER(TRIM(G56))="emea","EMEA",IF(LOWER(TRIM(G56))="apac","APAC",IF(LOWER(TRIM(G56))="latam","LATAM",TRIM(G56)))))) -> EMEA | N56: =VALUE(SUBSTITUTE(SUBSTITUTE(SUBSTITUTE(I56,"$",""),",",""),".",",")) -> 42.45 | O56: =IF(OR(H56="",N56=""),"",H56*N56) -> 212.25
A57: D-1056 | B57: 45715 | C57: Orbit Co | D57: Starter Plan | E57: Aisha Hassan | F57: Sarah Chen | G57: latam | H57: 2 | I57: 77.48 | J57: $154.96 | K57: Starter Plan | L57: =TRIM(E57) -> Aisha Hassan | M57: =IF(G57="","",IF(LOWER(TRIM(G57))="north america","North America",IF(LOWER(TRIM(G57))="emea","EMEA",IF(LOWER(TRIM(G57))="apac","APAC",IF(LOWER(TRIM(G57))="latam","LATAM",TRIM(G57)))))) -> LATAM | N57: =VALUE(SUBSTITUTE(SUBSTITUTE(SUBSTITUTE(I57,"$",""),",",""),".",",")) -> 77.48 | O57: =IF(OR(H57="",N57=""),"",H57*N57) -> 154.96
A58: D-1057 | B58: 45736 | C58: Arcadia Inc | D58: Business Plan | E58: Marcus Johnson | F58: Sarah Chen | G58: EMEA | H58: 2 | I58: 421.73 | J58: 843.46 | K58: Business Plan | L58: =TRIM(E58) -> Marcus Johnson | M58: =IF(G58="","",IF(LOWER(TRIM(G58))="north america","North America",IF(LOWER(TRIM(G58))="emea","EMEA",IF(LOWER(TRIM(G58))="apac","APAC",IF(LOWER(TRIM(G58))="latam","LATAM",TRIM(G58)))))) -> EMEA | N58: =VALUE(SUBSTITUTE(SUBSTITUTE(SUBSTITUTE(I58,"$",""),",",""),".",",")) -> 421.73 | O58: =IF(OR(H58="",N58=""),"",H58*N58) -> 843.46
A59: D-1058 | B59: 45670 | C59: Nimbus Co | D59: Business Plan | E59: Marcus Johnson | F59: Sarah Chen | G59: APAC | H59: 5 | I59: 422.7 | J59: 77919 | K59: Business Plan | L59: =TRIM(E59) -> Marcus Johnson | M59: =IF(G59="","",IF(LOWER(TRIM(G59))="north america","North America",IF(LOWER(TRIM(G59))="emea","EMEA",IF(LOWER(TRIM(G59))="apac","APAC",IF(LOWER(TRIM(G59))="latam","LATAM",TRIM(G59)))))) -> APAC | N59: =VALUE(SUBSTITUTE(SUBSTITUTE(SUBSTITUTE(I59,"$",""),",",""),".",",")) -> 422.7 | O59: =IF(OR(H59="",N59=""),"",H59*N59) -> 2113.5
A60: D-1059 | B60: 45689 | C60: Phoenix Co | D60: Add-on: Analytics | E60: Carlos Mendez | F60: Maya Rodriguez | G60: EMEA | H60: 1 | I60: 104.29 | J60: 104.29 | K60: Add-on: Analytics | L60: =TRIM(E60) -> Carlos Mendez | M60: =IF(G60="","",IF(LOWER(TRIM(G60))="north america","North America",IF(LOWER(TRIM(G60))="emea","EMEA",IF(LOWER(TRIM(G60))="apac","APAC",IF(LOWER(TRIM(G60))="latam","LATAM",TRIM(G60)))))) -> EMEA | N60: =VALUE(SUBSTITUTE(SUBSTITUTE(SUBSTITUTE(I60,"$",""),",",""),".",",")) -> 104.29 | O60: =IF(OR(H60="",N60=""),"",H60*N60) -> 104.29
A61: D-1060 | B61: 45727 | C61: Meridian Group | D61: Starter Plan | E61: Aisha Hassan | F61: Sarah Chen | G61: APAC | H61: 5 | I61: 60.18 | J61: $300.9 | K61: Starter Plan | L61: =TRIM(E61) -> Aisha Hassan | M61: =IF(G61="","",IF(LOWER(TRIM(G61))="north america","North America",IF(LOWER(TRIM(G61))="emea","EMEA",IF(LOWER(TRIM(G61))="apac","APAC",IF(LOWER(TRIM(G61))="latam","LATAM",TRIM(G61)))))) -> APAC | N61: =VALUE(SUBSTITUTE(SUBSTITUTE(SUBSTITUTE(I61,"$",""),",",""),".",",")) -> 60.18 | O61: =IF(OR(H61="",N61=""),"",H61*N61) -> 300.9
A62: D-1061 | B62: 45725 | C62: Nimbus Co | D62: Pro Plan | E62: Marcus Johnson | F62: Sarah Chen | G62: EMEA | H62: 5 | I62: 213.15 | J62: $1,065.75 | K62: Pro Plan | L62: =TRIM(E62) -> Marcus Johnson | M62: =IF(G62="","",IF(LOWER(TRIM(G62))="north america","North America",IF(LOWER(TRIM(G62))="emea","EMEA",IF(LOWER(TRIM(G62))="apac","APAC",IF(LOWER(TRIM(G62))="latam","LATAM",TRIM(G62)))))) -> EMEA | N62: =VALUE(SUBSTITUTE(SUBSTITUTE(SUBSTITUTE(I62,"$",""),",",""),".",",")) -> 213.15 | O62: =IF(OR(H62="",N62=""),"",H62*N62) -> 1065.75
A63: D-1062 | B63: 45682 | C63: Onyx Group | D63: Starter Plan | E63: Sophie Laurent | F63: Maya Rodriguez | G63: North America | H63: 10 | I63: 53.37 | J63: 533.7 | K63: Starter Plan | L63: =TRIM(E63) -> Sophie Laurent | M63: =IF(G63="","",IF(LOWER(TRIM(G63))="north america","North America",IF(LOWER(TRIM(G63))="emea","EMEA",IF(LOWER(TRIM(G63))="apac","APAC",IF(LOWER(TRIM(G63))="latam","LATAM",TRIM(G63)))))) -> North America | N63: =VALUE(SUBSTITUTE(SUBSTITUTE(SUBSTITUTE(I63,"$",""),",",""),".",",")) -> 53.37 | O63: =IF(OR(H63="",N63=""),"",H63*N63) -> 533.7
A64: D-1063 | B64: 45664 | C64: Granite Co | D64: Add-on: Support | E64: Marcus Johnson | F64: Sarah Chen | G64: North America | H64: 1 | I64: 93.27 | J64: 93.27 | K64: Add-on: Support | L64: =TRIM(E64) -> Marcus Johnson | M64: =IF(G64="","",IF(LOWER(TRIM(G64))="north america","North America",IF(LOWER(TRIM(G64))="emea","EMEA",IF(LOWER(TRIM(G64))="apac","APAC",IF(LOWER(TRIM(G64))="latam","LATAM",TRIM(G64)))))) -> North America | N64: =VALUE(SUBSTITUTE(SUBSTITUTE(SUBSTITUTE(I64,"$",""),",",""),".",",")) -> 93.27 | O64: =IF(OR(H64="",N64=""),"",H64*N64) -> 93.27
A65: D-1064 | B65: 45683 | C65: Solstice Group | D65: BUSINESS PLAN | E65: Elena Rossi | F65: Lukas Becker | G65: APAC | H65: 1 | I65: 61.21 | J65: 61.21 | K65: Business Plan | L65: =TRIM(E65) -> Elena Rossi | M65: =IF(G65="","",IF(LOWER(TRIM(G65))="north america","North America",IF(LOWER(TRIM(G65))="emea","EMEA",IF(LOWER(TRIM(G65))="apac","APAC",IF(LOWER(TRIM(G65))="latam","LATAM",TRIM(G65)))))) -> APAC | N65: =VALUE(SUBSTITUTE(SUBSTITUTE(SUBSTITUTE(I65,"$",""),",",""),".",",")) -> 61.21 | O65: =IF(OR(H65="",N65=""),"",H65*N65) -> 61.21
...

Sheet Zusammenfassung
A1: PeakFlow Q1 2025 - Sales Summery
A3: Anzahl Deals | D3: =COUNTA(A100:A1038) -> 264
A4: Summe Revenue | D4: =SUM(J100:J349) -> 364634.55
A5: Mittelwert Geschäftumsatz | D5: =AVERAGE(J100:J349) -> 1458.5382
A6: Median Geschäftumsatz | D6: =MEDIAN(J100:J349) -> 386.76
A7: Minimum | D7: =MIN(J99:J342) -> 41.17
A8: Maximum | D8: =MAX(J99:J342) -> 46616
A9: Bereich | D9: =MAX(J99:J342)-MIN(J99:J342) -> 46574.83
A10: Standardabweichung | D10: =STDEV(J99:J349) -> 4165.1839
A11: 1. Quartil (Q1) | D11: =QUARTILE(J99:J342,1) -> 131.395
A12: 3. Quartil (Q3) | D12: =QUARTILE(J99:J342,3) -> 994.38
A14: Wie sieht ein typischer Deal im ersten Quartal aus? Der typische Deal im ersten Quartal weist einen Umsatz von 386,76 € auf. Dieser Wert entspricht dem Median und beschreibt den typischen Geschäftsumsatz besser als der Mittelwert, da der Median nicht von einzelnen außergewöhnlich hohen Umsätzen beeinflusst wird.
A16: Vergleich von Mittelwert und Median Der Mittelwert beträgt 1.458,54 € und liegt damit deutlich über dem Median von 386,76 €. Diese Abweichung deutet auf eine rechtsschiefe Verteilung der Umsätze hin. Einige wenige umsatzstarke Deals erhöhen den Durchschnitt erheblich, während der Großteil der Geschäfte deutlich niedrigere Umsätze erzielt. Der hohe Maximalwert von 46.616,00 € bestätigt das Vorhandensein solcher Ausreißer. Daher eignet sich der Median besser, um den typischen Umsatz eines Deals zu beschreiben.
A19: Performance by Sale Rep
B20: Category Name
A21: Sales Rep | B21: {=TRANSPOSE(_xlfn.UNIQUE(_xlfn._xlws.FILTER(D100:D1038,D100:D1038<>"")))} -> Starter Plan | C21: Pro Plan | D21: Enterprise Plan | E21: Business Plan | F21: Add-on: Support | G21: Add-on: Analytics
A22: {=_xlfn.UNIQUE(_xlfn._xlws.FILTER(E100:E1038,E100:E1038<>""))} -> Priya Patel | B22: =IF(COUNTIFS($E$100:$E$1038,$A22,$D$100:$D$1038,B$21)=0,"keine Daten vorhanden",SUMIFS($J$100:$J$1038,$E$100:$E$1038,$A22,$D$100:$D$1038,B$21)) -> 425.02 | C22: =IF(COUNTIFS($E$100:$E$1038,$A22,$D$100:$D$1038,C$21)=0,"keine Daten vorhanden",SUMIFS($J$100:$J$1038,$E$100:$E$1038,$A22,$D$100:$D$1038,C$21)) -> 3380.64 | D22: =IF(COUNTIFS($E$100:$E$1038,$A22,$D$100:$D$1038,D$21)=0,"keine Daten vorhanden",SUMIFS($J$100:$J$1038,$E$100:$E$1038,$A22,$D$100:$D$1038,D$21)) -> 2728.47 | E22: =IF(COUNTIFS($E$100:$E$1038,$A22,$D$100:$D$1038,E$21)=0,"keine Daten vorhanden",SUMIFS($J$100:$J$1038,$E$100:$E$1038,$A22,$D$100:$D$1038,E$21)) -> 1377.55 | F22: =IF(COUNTIFS($E$100:$E$1038,$A22,$D$100:$D$1038,F$21)=0,"keine Daten vorhanden",SUMIFS($J$100:$J$1038,$E$100:$E$1038,$A22,$D$100:$D$1038,F$21)) -> 1882.42 | G22: =IF(COUNTIFS($E$100:$E$1038,$A22,$D$100:$D$1038,G$21)=0,"keine Daten vorhanden",SUMIFS($J$100:$J$1038,$E$100:$E$1038,$A22,$D$100:$D$1038,G$21)) -> 515.5
A23: David Kim | B23: =IF(COUNTIFS($E$100:$E$1038,$A23,$D$100:$D$1038,B$21)=0,"keine Daten vorhanden",SUMIFS($J$100:$J$1038,$E$100:$E$1038,$A23,$D$100:$D$1038,B$21)) -> 2509.99 | C23: =IF(COUNTIFS($E$100:$E$1038,$A23,$D$100:$D$1038,C$21)=0,"keine Daten vorhanden",SUMIFS($J$100:$J$1038,$E$100:$E$1038,$A23,$D$100:$D$1038,C$21)) -> 6607.08 | D23: =IF(COUNTIFS($E$100:$E$1038,$A23,$D$100:$D$1038,D$21)=0,"keine Daten vorhanden",SUMIFS($J$100:$J$1038,$E$100:$E$1038,$A23,$D$100:$D$1038,D$21)) -> 26430.16 | E23: =IF(COUNTIFS($E$100:$E$1038,$A23,$D$100:$D$1038,E$21)=0,"keine Daten vorhanden",SUMIFS($J$100:$J$1038,$E$100:$E$1038,$A23,$D$100:$D$1038,E$21)) -> 3858.23 | F23: =IF(COUNTIFS($E$100:$E$1038,$A23,$D$100:$D$1038,F$21)=0,"keine Daten vorhanden",SUMIFS($J$100:$J$1038,$E$100:$E$1038,$A23,$D$100:$D$1038,F$21)) -> keine Daten vorhanden | G23: =IF(COUNTIFS($E$100:$E$1038,$A23,$D$100:$D$1038,G$21)=0,"keine Daten vorhanden",SUMIFS($J$100:$J$1038,$E$100:$E$1038,$A23,$D$100:$D$1038,G$21)) -> 1647.13
A24: Carlos Mendez | B24: =IF(COUNTIFS($E$100:$E$1038,$A24,$D$100:$D$1038,B$21)=0,"keine Daten vorhanden",SUMIFS($J$100:$J$1038,$E$100:$E$1038,$A24,$D$100:$D$1038,B$21)) -> 4610.26 | C24: =IF(COUNTIFS($E$100:$E$1038,$A24,$D$100:$D$1038,C$21)=0,"keine Daten vorhanden",SUMIFS($J$100:$J$1038,$E$100:$E$1038,$A24,$D$100:$D$1038,C$21)) -> 3745.67 | D24: =IF(COUNTIFS($E$100:$E$1038,$A24,$D$100:$D$1038,D$21)=0,"keine Daten vorhanden",SUMIFS($J$100:$J$1038,$E$100:$E$1038,$A24,$D$100:$D$1038,D$21)) -> 15653.27 | E24: =IF(COUNTIFS($E$100:$E$1038,$A24,$D$100:$D$1038,E$21)=0,"keine Daten vorhanden",SUMIFS($J$100:$J$1038,$E$100:$E$1038,$A24,$D$100:$D$1038,E$21)) -> 403.84 | F24: =IF(COUNTIFS($E$100:$E$1038,$A24,$D$100:$D$1038,F$21)=0,"keine Daten vorhanden",SUMIFS($J$100:$J$1038,$E$100:$E$1038,$A24,$D$100:$D$1038,F$21)) -> 114.94 | G24: =IF(COUNTIFS($E$100:$E$1038,$A24,$D$100:$D$1038,G$21)=0,"keine Daten vorhanden",SUMIFS($J$100:$J$1038,$E$100:$E$1038,$A24,$D$100:$D$1038,G$21)) -> 183.21
A25: Aisha Hassan | B25: =IF(COUNTIFS($E$100:$E$1038,$A25,$D$100:$D$1038,B$21)=0,"keine Daten vorhanden",SUMIFS($J$100:$J$1038,$E$100:$E$1038,$A25,$D$100:$D$1038,B$21)) -> 1173.93 | C25: =IF(COUNTIFS($E$100:$E$1038,$A25,$D$100:$D$1038,C$21)=0,"keine Daten vorhanden",SUMIFS($J$100:$J$1038,$E$100:$E$1038,$A25,$D$100:$D$1038,C$21)) -> 15262.84 | D25: =IF(COUNTIFS($E$100:$E$1038,$A25,$D$100:$D$1038,D$21)=0,"keine Daten vorhanden",SUMIFS($J$100:$J$1038,$E$100:$E$1038,$A25,$D$100:$D$1038,D$21)) -> 12154 | E25: =IF(COUNTIFS($E$100:$E$1038,$A25,$D$100:$D$1038,E$21)=0,"keine Daten vorhanden",SUMIFS($J$100:$J$1038,$E$100:$E$1038,$A25,$D$100:$D$1038,E$21)) -> 4427.08 | F25: =IF(COUNTIFS($E$100:$E$1038,$A25,$D$100:$D$1038,F$21)=0,"keine Daten vorhanden",SUMIFS($J$100:$J$1038,$E$100:$E$1038,$A25,$D$100:$D$1038,F$21)) -> 249.04 | G25: =IF(COUNTIFS($E$100:$E$1038,$A25,$D$100:$D$1038,G$21)=0,"keine Daten vorhanden",SUMIFS($J$100:$J$1038,$E$100:$E$1038,$A25,$D$100:$D$1038,G$21)) -> 604.26
A26: Elena Rossi | B26: =IF(COUNTIFS($E$100:$E$1038,$A26,$D$100:$D$1038,B$21)=0,"keine Daten vorhanden",SUMIFS($J$100:$J$1038,$E$100:$E$1038,$A26,$D$100:$D$1038,B$21)) -> 3973.4 | C26: =IF(COUNTIFS($E$100:$E$1038,$A26,$D$100:$D$1038,C$21)=0,"keine Daten vorhanden",SUMIFS($J$100:$J$1038,$E$100:$E$1038,$A26,$D$100:$D$1038,C$21)) -> 996.5 | D26: =IF(COUNTIFS($E$100:$E$1038,$A26,$D$100:$D$1038,D$21)=0,"keine Daten vorhanden",SUMIFS($J$100:$J$1038,$E$100:$E$1038,$A26,$D$100:$D$1038,D$21)) -> 4503.4 | E26: =IF(COUNTIFS($E$100:$E$1038,$A26,$D$100:$D$1038,E$21)=0,"keine Daten vorhanden",SUMIFS($J$100:$J$1038,$E$100:$E$1038,$A26,$D$100:$D$1038,E$21)) -> 10192.24 | F26: =IF(COUNTIFS($E$100:$E$1038,$A26,$D$100:$D$1038,F$21)=0,"keine Daten vorhanden",SUMIFS($J$100:$J$1038,$E$100:$E$1038,$A26,$D$100:$D$1038,F$21)) -> 198.53 | G26: =IF(COUNTIFS($E$100:$E$1038,$A26,$D$100:$D$1038,G$21)=0,"keine Daten vorhanden",SUMIFS($J$100:$J$1038,$E$100:$E$1038,$A26,$D$100:$D$1038,G$21)) -> 373.45
A27: Nina Petrov | B27: =IF(COUNTIFS($E$100:$E$1038,$A27,$D$100:$D$1038,B$21)=0,"keine Daten vorhanden",SUMIFS($J$100:$J$1038,$E$100:$E$1038,$A27,$D$100:$D$1038,B$21)) -> 1107.58 | C27: =IF(COUNTIFS($E$100:$E$1038,$A27,$D$100:$D$1038,C$21)=0,"keine Daten vorhanden",SUMIFS($J$100:$J$1038,$E$100:$E$1038,$A27,$D$100:$D$1038,C$21)) -> 14152.34 | D27: =IF(COUNTIFS($E$100:$E$1038,$A27,$D$100:$D$1038,D$21)=0,"keine Daten vorhanden",SUMIFS($J$100:$J$1038,$E$100:$E$1038,$A27,$D$100:$D$1038,D$21)) -> 47925.46 | E27: =IF(COUNTIFS($E$100:$E$1038,$A27,$D$100:$D$1038,E$21)=0,"keine Daten vorhanden",SUMIFS($J$100:$J$1038,$E$100:$E$1038,$A27,$D$100:$D$1038,E$21)) -> 1199.6 | F27: =IF(COUNTIFS($E$100:$E$1038,$A27,$D$100:$D$1038,F$21)=0,"keine Daten vorhanden",SUMIFS($J$100:$J$1038,$E$100:$E$1038,$A27,$D$100:$D$1038,F$21)) -> 294.63 | G27: =IF(COUNTIFS($E$100:$E$1038,$A27,$D$100:$D$1038,G$21)=0,"keine Daten vorhanden",SUMIFS($J$100:$J$1038,$E$100:$E$1038,$A27,$D$100:$D$1038,G$21)) -> 95.13
A28: Tom Wilson | B28: =IF(COUNTIFS($E$100:$E$1038,$A28,$D$100:$D$1038,B$21)=0,"keine Daten vorhanden",SUMIFS($J$100:$J$1038,$E$100:$E$1038,$A28,$D$100:$D$1038,B$21)) -> 1406.89 | C28: =IF(COUNTIFS($E$100:$E$1038,$A28,$D$100:$D$1038,C$21)=0,"keine Daten vorhanden",SUMIFS($J$100:$J$1038,$E$100:$E$1038,$A28,$D$100:$D$1038,C$21)) -> 10276.16 | D28: =IF(COUNTIFS($E$100:$E$1038,$A28,$D$100:$D$1038,D$21)=0,"keine Daten vorhanden",SUMIFS($J$100:$J$1038,$E$100:$E$1038,$A28,$D$100:$D$1038,D$21)) -> 1227.17 | E28: =IF(COUNTIFS($E$100:$E$1038,$A28,$D$100:$D$1038,E$21)=0,"keine Daten vorhanden",SUMIFS($J$100:$J$1038,$E$100:$E$1038,$A28,$D$100:$D$1038,E$21)) -> 1335.01 | F28: =IF(COUNTIFS($E$100:$E$1038,$A28,$D$100:$D$1038,F$21)=0,"keine Daten vorhanden",SUMIFS($J$100:$J$1038,$E$100:$E$1038,$A28,$D$100:$D$1038,F$21)) -> 330.86 | G28: =IF(COUNTIFS($E$100:$E$1038,$A28,$D$100:$D$1038,G$21)=0,"keine Daten vorhanden",SUMIFS($J$100:$J$1038,$E$100:$E$1038,$A28,$D$100:$D$1038,G$21)) -> 825.73
A29: Marcus Johnson | B29: =IF(COUNTIFS($E$100:$E$1038,$A29,$D$100:$D$1038,B$21)=0,"keine Daten vorhanden",SUMIFS($J$100:$J$1038,$E$100:$E$1038,$A29,$D$100:$D$1038,B$21)) -> 747.95 | C29: =IF(COUNTIFS($E$100:$E$1038,$A29,$D$100:$D$1038,C$21)=0,"keine Daten vorhanden",SUMIFS($J$100:$J$1038,$E$100:$E$1038,$A29,$D$100:$D$1038,C$21)) -> 8780.22 | D29: =IF(COUNTIFS($E$100:$E$1038,$A29,$D$100:$D$1038,D$21)=0,"keine Daten vorhanden",SUMIFS($J$100:$J$1038,$E$100:$E$1038,$A29,$D$100:$D$1038,D$21)) -> 56800.24 | E29: =IF(COUNTIFS($E$100:$E$1038,$A29,$D$100:$D$1038,E$21)=0,"keine Daten vorhanden",SUMIFS($J$100:$J$1038,$E$100:$E$1038,$A29,$D$100:$D$1038,E$21)) -> 10763.03 | F29: =IF(COUNTIFS($E$100:$E$1038,$A29,$D$100:$D$1038,F$21)=0,"keine Daten vorhanden",SUMIFS($J$100:$J$1038,$E$100:$E$1038,$A29,$D$100:$D$1038,F$21)) -> 1163.97 | G29: =IF(COUNTIFS($E$100:$E$1038,$A29,$D$100:$D$1038,G$21)=0,"keine Daten vorhanden",SUMIFS($J$100:$J$1038,$E$100:$E$1038,$A29,$D$100:$D$1038,G$21)) -> 696.56
A30: James Park | B30: =IF(COUNTIFS($E$100:$E$1038,$A30,$D$100:$D$1038,B$21)=0,"keine Daten vorhanden",SUMIFS($J$100:$J$1038,$E$100:$E$1038,$A30,$D$100:$D$1038,B$21)) -> 2475.44 | C30: =IF(COUNTIFS($E$100:$E$1038,$A30,$D$100:$D$1038,C$21)=0,"keine Daten vorhanden",SUMIFS($J$100:$J$1038,$E$100:$E$1038,$A30,$D$100:$D$1038,C$21)) -> 4790.61 | D30: =IF(COUNTIFS($E$100:$E$1038,$A30,$D$100:$D$1038,D$21)=0,"keine Daten vorhanden",SUMIFS($J$100:$J$1038,$E$100:$E$1038,$A30,$D$100:$D$1038,D$21)) -> 2533 | E30: =IF(COUNTIFS($E$100:$E$1038,$A30,$D$100:$D$1038,E$21)=0,"keine Daten vorhanden",SUMIFS($J$100:$J$1038,$E$100:$E$1038,$A30,$D$100:$D$1038,E$21)) -> 3076.84 | F30: =IF(COUNTIFS($E$100:$E$1038,$A30,$D$100:$D$1038,F$21)=0,"keine Daten vorhanden",SUMIFS($J$100:$J$1038,$E$100:$E$1038,$A30,$D$100:$D$1038,F$21)) -> keine Daten vorhanden | G30: =IF(COUNTIFS($E$100:$E$1038,$A30,$D$100:$D$1038,G$21)=0,"keine Daten vorhanden",SUMIFS($J$100:$J$1038,$E$100:$E$1038,$A30,$D$100:$D$1038,G$21)) -> 2319.25
A31: Raj Sharma | B31: =IF(COUNTIFS($E$100:$E$1038,$A31,$D$100:$D$1038,B$21)=0,"keine Daten vorhanden",SUMIFS($J$100:$J$1038,$E$100:$E$1038,$A31,$D$100:$D$1038,B$21)) -> 3078.66 | C31: =IF(COUNTIFS($E$100:$E$1038,$A31,$D$100:$D$1038,C$21)=0,"keine Daten vorhanden",SUMIFS($J$100:$J$1038,$E$100:$E$1038,$A31,$D$100:$D$1038,C$21)) -> 11872.97 | D31: =IF(COUNTIFS($E$100:$E$1038,$A31,$D$100:$D$1038,D$21)=0,"keine Daten vorhanden",SUMIFS($J$100:$J$1038,$E$100:$E$1038,$A31,$D$100:$D$1038,D$21)) -> keine Daten vorhanden | E31: =IF(COUNTIFS($E$100:$E$1038,$A31,$D$100:$D$1038,E$21)=0,"keine Daten vorhanden",SUMIFS($J$100:$J$1038,$E$100:$E$1038,$A31,$D$100:$D$1038,E$21)) -> 7365.2 | F31: =IF(COUNTIFS($E$100:$E$1038,$A31,$D$100:$D$1038,F$21)=0,"keine Daten vorhanden",SUMIFS($J$100:$J$1038,$E$100:$E$1038,$A31,$D$100:$D$1038,F$21)) -> keine Daten vorhanden | G31: =IF(COUNTIFS($E$100:$E$1038,$A31,$D$100:$D$1038,G$21)=0,"keine Daten vorhanden",SUMIFS($J$100:$J$1038,$E$100:$E$1038,$A31,$D$100:$D$1038,G$21)) -> 95.39
A32: Sophie Laurent | B32: =IF(COUNTIFS($E$100:$E$1038,$A32,$D$100:$D$1038,B$21)=0,"keine Daten vorhanden",SUMIFS($J$100:$J$1038,$E$100:$E$1038,$A32,$D$100:$D$1038,B$21)) -> 5819.56 | C32: =IF(COUNTIFS($E$100:$E$1038,$A32,$D$100:$D$1038,C$21)=0,"keine Daten vorhanden",SUMIFS($J$100:$J$1038,$E$100:$E$1038,$A32,$D$100:$D$1038,C$21)) -> 1177.11 | D32: =IF(COUNTIFS($E$100:$E$1038,$A32,$D$100:$D$1038,D$21)=0,"keine Daten vorhanden",SUMIFS($J$100:$J$1038,$E$100:$E$1038,$A32,$D$100:$D$1038,D$21)) -> 958.86 | E32: =IF(COUNTIFS($E$100:$E$1038,$A32,$D$100:$D$1038,E$21)=0,"keine Daten vorhanden",SUMIFS($J$100:$J$1038,$E$100:$E$1038,$A32,$D$100:$D$1038,E$21)) -> 4908.2 | F32: =IF(COUNTIFS($E$100:$E$1038,$A32,$D$100:$D$1038,F$21)=0,"keine Daten vorhanden",SUMIFS($J$100:$J$1038,$E$100:$E$1038,$A32,$D$100:$D$1038,F$21)) -> 2214.32 | G32: =IF(COUNTIFS($E$100:$E$1038,$A32,$D$100:$D$1038,G$21)=0,"keine Daten vorhanden",SUMIFS($J$100:$J$1038,$E$100:$E$1038,$A32,$D$100:$D$1038,G$21)) -> 104.56
A33: Hannah Lee | B33: =IF(COUNTIFS($E$100:$E$1038,$A33,$D$100:$D$1038,B$21)=0,"keine Daten vorhanden",SUMIFS($J$100:$J$1038,$E$100:$E$1038,$A33,$D$100:$D$1038,B$21)) -> 4840.27 | C33: =IF(COUNTIFS($E$100:$E$1038,$A33,$D$100:$D$1038,C$21)=0,"keine Daten vorhanden",SUMIFS($J$100:$J$1038,$E$100:$E$1038,$A33,$D$100:$D$1038,C$21)) -> 4164.71 | D33: =IF(COUNTIFS($E$100:$E$1038,$A33,$D$100:$D$1038,D$21)=0,"keine Daten vorhanden",SUMIFS($J$100:$J$1038,$E$100:$E$1038,$A33,$D$100:$D$1038,D$21)) -> keine Daten vorhanden | E33: =IF(COUNTIFS($E$100:$E$1038,$A33,$D$100:$D$1038,E$21)=0,"keine Daten vorhanden",SUMIFS($J$100:$J$1038,$E$100:$E$1038,$A33,$D$100:$D$1038,E$21)) -> 7524.34 | F33: =IF(COUNTIFS($E$100:$E$1038,$A33,$D$100:$D$1038,F$21)=0,"keine Daten vorhanden",SUMIFS($J$100:$J$1038,$E$100:$E$1038,$A33,$D$100:$D$1038,F$21)) -> 1759.48 | G33: =IF(COUNTIFS($E$100:$E$1038,$A33,$D$100:$D$1038,G$21)=0,"keine Daten vorhanden",SUMIFS($J$100:$J$1038,$E$100:$E$1038,$A33,$D$100:$D$1038,G$21)) -> 4245.2
A36: Performance by Sale Rep
B37: Region
A38: Sales Rep | B38: APAC | C38: EMEA | D38: LATAM | E38: North America
A39: {=_xlfn.UNIQUE(_xlfn._xlws.FILTER(E100:E1038,E100:E1038<>""))} -> Priya Patel | B39: =IF(COUNTIFS($E$100:$E$1038,$A39,$G$100:$G$1038,B$38)=0,"keine Daten vorhanden",SUMIFS($J$100:$J$1038,$E$100:$E$1038,$A39,$G$100:$G$1038,B$38)) -> 2310.33 | C39: =IF(COUNTIFS($E$100:$E$1038,$A39,$G$100:$G$1038,C$38)=0,"keine Daten vorhanden",SUMIFS($J$100:$J$1038,$E$100:$E$1038,$A39,$G$100:$G$1038,C$38)) -> 3060.53 | D39: =IF(COUNTIFS($E$100:$E$1038,$A39,$G$100:$G$1038,D$38)=0,"keine Daten vorhanden",SUMIFS($J$100:$J$1038,$E$100:$E$1038,$A39,$G$100:$G$1038,D$38)) -> 2125.56 | E39: =IF(COUNTIFS($E$100:$E$1038,$A39,$G$100:$G$1038,E$38)=0,"keine Daten vorhanden",SUMIFS($J$100:$J$1038,$E$100:$E$1038,$A39,$G$100:$G$1038,E$38)) -> 2813.18
A40: David Kim | B40: =IF(COUNTIFS($E$100:$E$1038,$A40,$G$100:$G$1038,B$38)=0,"keine Daten vorhanden",SUMIFS($J$100:$J$1038,$E$100:$E$1038,$A40,$G$100:$G$1038,B$38)) -> 1075.49 | C40: =IF(COUNTIFS($E$100:$E$1038,$A40,$G$100:$G$1038,C$38)=0,"keine Daten vorhanden",SUMIFS($J$100:$J$1038,$E$100:$E$1038,$A40,$G$100:$G$1038,C$38)) -> 8161.66 | D40: =IF(COUNTIFS($E$100:$E$1038,$A40,$G$100:$G$1038,D$38)=0,"keine Daten vorhanden",SUMIFS($J$100:$J$1038,$E$100:$E$1038,$A40,$G$100:$G$1038,D$38)) -> 24600.09 | E40: =IF(COUNTIFS($E$100:$E$1038,$A40,$G$100:$G$1038,E$38)=0,"keine Daten vorhanden",SUMIFS($J$100:$J$1038,$E$100:$E$1038,$A40,$G$100:$G$1038,E$38)) -> 7215.35
A41: Carlos Mendez | B41: =IF(COUNTIFS($E$100:$E$1038,$A41,$G$100:$G$1038,B$38)=0,"keine Daten vorhanden",SUMIFS($J$100:$J$1038,$E$100:$E$1038,$A41,$G$100:$G$1038,B$38)) -> 4015.28 | C41: =IF(COUNTIFS($E$100:$E$1038,$A41,$G$100:$G$1038,C$38)=0,"keine Daten vorhanden",SUMIFS($J$100:$J$1038,$E$100:$E$1038,$A41,$G$100:$G$1038,C$38)) -> 16125.9 | D41: =IF(COUNTIFS($E$100:$E$1038,$A41,$G$100:$G$1038,D$38)=0,"keine Daten vorhanden",SUMIFS($J$100:$J$1038,$E$100:$E$1038,$A41,$G$100:$G$1038,D$38)) -> 3357.63 | E41: =IF(COUNTIFS($E$100:$E$1038,$A41,$G$100:$G$1038,E$38)=0,"keine Daten vorhanden",SUMIFS($J$100:$J$1038,$E$100:$E$1038,$A41,$G$100:$G$1038,E$38)) -> 1212.38
A42: Aisha Hassan | B42: =IF(COUNTIFS($E$100:$E$1038,$A42,$G$100:$G$1038,B$38)=0,"keine Daten vorhanden",SUMIFS($J$100:$J$1038,$E$100:$E$1038,$A42,$G$100:$G$1038,B$38)) -> 13491.73 | C42: =IF(COUNTIFS($E$100:$E$1038,$A42,$G$100:$G$1038,C$38)=0,"keine Daten vorhanden",SUMIFS($J$100:$J$1038,$E$100:$E$1038,$A42,$G$100:$G$1038,C$38)) -> 667.97 | D42: =IF(COUNTIFS($E$100:$E$1038,$A42,$G$100:$G$1038,D$38)=0,"keine Daten vorhanden",SUMIFS($J$100:$J$1038,$E$100:$E$1038,$A42,$G$100:$G$1038,D$38)) -> 5480.51 | E42: =IF(COUNTIFS($E$100:$E$1038,$A42,$G$100:$G$1038,E$38)=0,"keine Daten vorhanden",SUMIFS($J$100:$J$1038,$E$100:$E$1038,$A42,$G$100:$G$1038,E$38)) -> 14230.94
A43: Elena Rossi | B43: =IF(COUNTIFS($E$100:$E$1038,$A43,$G$100:$G$1038,B$38)=0,"keine Daten vorhanden",SUMIFS($J$100:$J$1038,$E$100:$E$1038,$A43,$G$100:$G$1038,B$38)) -> 17856.3 | C43: =IF(COUNTIFS($E$100:$E$1038,$A43,$G$100:$G$1038,C$38)=0,"keine Daten vorhanden",SUMIFS($J$100:$J$1038,$E$100:$E$1038,$A43,$G$100:$G$1038,C$38)) -> 112.19 | D43: =IF(COUNTIFS($E$100:$E$1038,$A43,$G$100:$G$1038,D$38)=0,"keine Daten vorhanden",SUMIFS($J$100:$J$1038,$E$100:$E$1038,$A43,$G$100:$G$1038,D$38)) -> 260.51 | E43: =IF(COUNTIFS($E$100:$E$1038,$A43,$G$100:$G$1038,E$38)=0,"keine Daten vorhanden",SUMIFS($J$100:$J$1038,$E$100:$E$1038,$A43,$G$100:$G$1038,E$38)) -> 2008.52
A44: Nina Petrov | B44: =IF(COUNTIFS($E$100:$E$1038,$A44,$G$100:$G$1038,B$38)=0,"keine Daten vorhanden",SUMIFS($J$100:$J$1038,$E$100:$E$1038,$A44,$G$100:$G$1038,B$38)) -> 47137.04 | C44: =IF(COUNTIFS($E$100:$E$1038,$A44,$G$100:$G$1038,C$38)=0,"keine Daten vorhanden",SUMIFS($J$100:$J$1038,$E$100:$E$1038,$A44,$G$100:$G$1038,C$38)) -> 3848.72 | D44: =IF(COUNTIFS($E$100:$E$1038,$A44,$G$100:$G$1038,D$38)=0,"keine Daten vorhanden",SUMIFS($J$100:$J$1038,$E$100:$E$1038,$A44,$G$100:$G$1038,D$38)) -> 11835.36 | E44: =IF(COUNTIFS($E$100:$E$1038,$A44,$G$100:$G$1038,E$38)=0,"keine Daten vorhanden",SUMIFS($J$100:$J$1038,$E$100:$E$1038,$A44,$G$100:$G$1038,E$38)) -> 1953.62
A45: Tom Wilson | B45: =IF(COUNTIFS($E$100:$E$1038,$A45,$G$100:$G$1038,B$38)=0,"keine Daten vorhanden",SUMIFS($J$100:$J$1038,$E$100:$E$1038,$A45,$G$100:$G$1038,B$38)) -> 1073.24 | C45: =IF(COUNTIFS($E$100:$E$1038,$A45,$G$100:$G$1038,C$38)=0,"keine Daten vorhanden",SUMIFS($J$100:$J$1038,$E$100:$E$1038,$A45,$G$100:$G$1038,C$38)) -> 3096 | D45: =IF(COUNTIFS($E$100:$E$1038,$A45,$G$100:$G$1038,D$38)=0,"keine Daten vorhanden",SUMIFS($J$100:$J$1038,$E$100:$E$1038,$A45,$G$100:$G$1038,D$38)) -> 8987.68 | E45: =IF(COUNTIFS($E$100:$E$1038,$A45,$G$100:$G$1038,E$38)=0,"keine Daten vorhanden",SUMIFS($J$100:$J$1038,$E$100:$E$1038,$A45,$G$100:$G$1038,E$38)) -> 2244.9
A46: Marcus Johnson | B46: =IF(COUNTIFS($E$100:$E$1038,$A46,$G$100:$G$1038,B$38)=0,"keine Daten vorhanden",SUMIFS($J$100:$J$1038,$E$100:$E$1038,$A46,$G$100:$G$1038,B$38)) -> 14117 | C46: =IF(COUNTIFS($E$100:$E$1038,$A46,$G$100:$G$1038,C$38)=0,"keine Daten vorhanden",SUMIFS($J$100:$J$1038,$E$100:$E$1038,$A46,$G$100:$G$1038,C$38)) -> 28295.08 | D46: =IF(COUNTIFS($E$100:$E$1038,$A46,$G$100:$G$1038,D$38)=0,"keine Daten vorhanden",SUMIFS($J$100:$J$1038,$E$100:$E$1038,$A46,$G$100:$G$1038,D$38)) -> 26328.69 | E46: =IF(COUNTIFS($E$100:$E$1038,$A46,$G$100:$G$1038,E$38)=0,"keine Daten vorhanden",SUMIFS($J$100:$J$1038,$E$100:$E$1038,$A46,$G$100:$G$1038,E$38)) -> 10211.2
A47: James Park | B47: =IF(COUNTIFS($E$100:$E$1038,$A47,$G$100:$G$1038,B$38)=0,"keine Daten vorhanden",SUMIFS($J$100:$J$1038,$E$100:$E$1038,$A47,$G$100:$G$1038,B$38)) -> 372.97 | C47: =IF(COUNTIFS($E$100:$E$1038,$A47,$G$100:$G$1038,C$38)=0,"keine Daten vorhanden",SUMIFS($J$100:$J$1038,$E$100:$E$1038,$A47,$G$100:$G$1038,C$38)) -> 4705.65 | D47: =IF(COUNTIFS($E$100:$E$1038,$A47,$G$100:$G$1038,D$38)=0,"keine Daten vorhanden",SUMIFS($J$100:$J$1038,$E$100:$E$1038,$A47,$G$100:$G$1038,D$38)) -> 784.01 | E47: =IF(COUNTIFS($E$100:$E$1038,$A47,$G$100:$G$1038,E$38)=0,"keine Daten vorhanden",SUMIFS($J$100:$J$1038,$E$100:$E$1038,$A47,$G$100:$G$1038,E$38)) -> 9332.51
...

Sheet Pivot-Tabellen
A1: SUM of Revenue | B1: CategoryName
A2: SalesRep | B2: Starter Plan | C2: Pro Plan | D2: Enterprise Plan | E2: Business Plan | F2: Add-on: Support | G2: Add-on: Analytics | H2: Gesamtergebnis
A3: Aisha Hassan | B3: 1173.93 | C3: 15262.84 | D3: 12154 | E3: 4427.08 | F3: 249.04 | G3: 604.26 | H3: 33871.15
A4: Carlos Mendez | B4: 4610.26 | C4: 3745.67 | D4: 15653.27 | E4: 403.84 | F4: 114.94 | G4: 183.21 | H4: 24711.19
A5: David Kim | B5: 2509.99 | C5: 6607.08 | D5: 26430.16 | E5: 3858.23 | G5: 1647.13 | H5: 41052.59
A6: Elena Rossi | B6: 3973.4 | C6: 996.5 | D6: 4503.4 | E6: 10192.24 | F6: 198.53 | G6: 373.45 | H6: 20237.52
A7: Hannah Lee | B7: 4840.27 | C7: 4164.71 | E7: 7524.34 | F7: 1759.48 | G7: 4245.2 | H7: 22534
A8: James Park | B8: 2475.44 | C8: 4790.61 | D8: 2533 | E8: 3076.84 | G8: 2319.25 | H8: 15195.14
A9: Marcus Johnson | B9: 747.95 | C9: 8780.22 | D9: 56800.24 | E9: 10763.03 | F9: 1163.97 | G9: 696.56 | H9: 78951.97
A10: Nina Petrov | B10: 1107.58 | C10: 14152.34 | D10: 47925.46 | E10: 1199.6 | F10: 294.63 | G10: 95.13 | H10: 64774.74
A11: Priya Patel | B11: 425.02 | C11: 3380.64 | D11: 2728.47 | E11: 1377.55 | F11: 1882.42 | G11: 515.5 | H11: 10309.6
A12: Raj Sharma | B12: 3078.66 | C12: 11872.97 | E12: 7365.2 | G12: 95.39 | H12: 22412.22
A13: Sophie Laurent | B13: 5819.56 | C13: 1177.11 | D13: 958.86 | E13: 4908.2 | F13: 2214.32 | G13: 104.56 | H13: 15182.61
A14: Tom Wilson | B14: 1406.89 | C14: 10276.16 | D14: 1227.17 | E14: 1335.01 | F14: 330.86 | G14: 825.73 | H14: 15401.82
A15: Gesamtergebnis | B15: 32168.95 | C15: 85206.85 | D15: 170914.03 | E15: 56431.16 | F15: 8208.19 | G15: 11705.37 | H15: 364634.55
A18: SUM of Revenue | B18: Region
A19: SalesRep | B19: APAC | C19: EMEA | D19: LATAM | E19: North America | F19: Gesamtergebnis
A20: Aisha Hassan | B20: 13491.73 | C20: 667.97 | D20: 5480.51 | E20: 14230.94 | F20: 33871.15
A21: Carlos Mendez | B21: 4015.28 | C21: 16125.9 | D21: 3357.63 | E21: 1212.38 | F21: 24711.19
A22: David Kim | B22: 1075.49 | C22: 8161.66 | D22: 24600.09 | E22: 7215.35 | F22: 41052.59
A23: Elena Rossi | B23: 17856.3 | C23: 112.19 | D23: 260.51 | E23: 2008.52 | F23: 20237.52
A24: Hannah Lee | B24: 7564.81 | C24: 275.18 | D24: 8172.73 | E24: 6521.28 | F24: 22534
A25: James Park | B25: 372.97 | C25: 4705.65 | D25: 784.01 | E25: 9332.51 | F25: 15195.14
A26: Marcus Johnson | B26: 14117 | C26: 28295.08 | D26: 26328.69 | E26: 10211.2 | F26: 78951.97
A27: Nina Petrov | B27: 47137.04 | C27: 3848.72 | D27: 11835.36 | E27: 1953.62 | F27: 64774.74
A28: Priya Patel | B28: 2310.33 | C28: 3060.53 | D28: 2125.56 | E28: 2813.18 | F28: 10309.6
A29: Raj Sharma | B29: 5953.04 | C29: 2149.66 | D29: 996 | E29: 13313.52 | F29: 22412.22
A30: Sophie Laurent | B30: 5058.26 | C30: 7650.38 | D30: 946.37 | E30: 1527.6 | F30: 15182.61
A31: Tom Wilson | B31: 1073.24 | C31: 3096 | D31: 8987.68 | E31: 2244.9 | F31: 15401.82
A32: Gesamtergebnis | B32: 120025.49 | C32: 78148.92 | D32: 93875.14 | E32: 72585 | F32: 364634.55
A36: Diegos Fragen:
A37: Wer ist in welcher Produktlinie stark?
A38: Wir haben eine klare Spezialisierung. Marcus Johnson und Nina Petrov sind unsere Schwergewichte im Enterprise-Bereich. David Kim ist unser unangefochtener Spezialist für Business-Pläne, der hier mehr Umsatz generiert als jeder andere Kollege in einer einzelnen Kategorie.
A42: Wem gehört welche Region?
A43: Die Verantwortlichkeiten sind geografisch klar verteilt. Nina Petrov ist die dominierende Kraft im APAC-Raum, während Marcus Johnson EMEA und David Kim LATAM anführen. In North America erzielt Aisha Hassan das beste Ergebnis, wobei der Markt hier im Vergleich zu APAC und EMEA weniger stark von einer einzelnen Person dominiert wird.

Sheet Top-Performer
A1: Top-Vertriebsmitarbeiter nach Anzahl der abgeschlossenen Geschäfte
A2: Vertriebsmitarbeiter | B2: Anzahl der Geschäfte
A3: Marcus Johnson | B3: 37
A4: Aisha Hassan | B4: 28
A5: David Kim | B5: 23
A6: Carlos Mendez | B6: 23
A7: Nina Petrov | B7: 22
A8: Priya Patel | B8: 21
A9: Hannah Lee | B9: 18
A10: Elena Rossi | B10: 17
A11: Raj Sharma | B11: 17
A12: Tom Wilson | B12: 16
A13: James Park | B13: 15
A14: Sophie Laurent | B14: 13
A17: Top-Vertriebsmitarbeiter nach durchschnittlichem Geschäftsvolumen
A18: Vertriebsmitarbeiter | B18: Duchschnittliches Geschäftvolumen
A19: Nina Petrov | B19: 2944.3064
A20: Marcus Johnson | B20: 2133.837
A21: David Kim | B21: 1784.8952
A22: Raj Sharma | B22: 1318.3659
A23: Hannah Lee | B23: 1251.8889
A24: Aisha Hassan | B24: 1209.6839
A25: Elena Rossi | B25: 1190.4424
A26: Sophie Laurent | B26: 1167.8931
A27: Carlos Mendez | B27: 1074.3996
A28: James Park | B28: 1013.0093
A29: Tom Wilson | B29: 962.61375
A30: Priya Patel | B30: 490.93333
A33: Die 10 größten Transaktionen des ersten Quartals
A34: Nina Petrov | B34: 46616
A35: David Kim | B35: 24064.6
A36: Marcus Johnson | B36: 23615.2
A37: Marcus Johnson | B37: 20087.4
A38: Carlos Mendez | B38: 13307.5
A39: Aisha Hassan | B39: 11180.7
A40: Aisha Hassan | B40: 10735.5
A41: Nina Petrov | B41: 10075.5
A42: Marcus Johnson | B42: 9870.6
A43: Elena Rossi | B43: 9741.8

Sheet Diagramme

Sheet README
A1: Arbeitsmappe „PeakFlow Q1 2025“ Diese Arbeitsmappe enthält die vollständige Analyse des Vertriebs im ersten Quartal 2025. Sie wurde erstellt, um die Leistung des Vertriebsteams transparent zu machen und strategische Fragen zur Umsatzverteilung und Mitarbeiterleistung zu beantworten. 1. Registerkarte: Datensätze Vorgehensweise: Import der Rohdaten aus der CSV-Datei. Bereinigung: Löschung von zwei Testzeilen (D-TEST1, D-TEST2), Korrektur von Tippfehlern bei Kategorien, Entfernung führender Leerzeichen bei den Vertriebsmitarbeitern und Vereinheitlichung der Spalte „Region“. Technik: Umwandlung der Spalten „UnitPrice“ und „Revenue“ in ein numerisches Zahlenformat. Kontrolle: Die Datenbasis umfasst nach der Bereinigung exakt 250 Transaktionen mit einem Gesamtumsatz von 364.634,55 €. 2. Registerkarte: Zusammenfassung Vorgehensweise: Anwendung statistischer Funktionen auf die Spalte „Revenue“. Methodik & verwendete Formeln: Anzahl der Deals: =COUNT(Revenue) → 250 Gesamtumsatz: =SUM(Revenue) → 364.634,55 € Mittelwert: =AVERAGE(Revenue) → 1.458,54 € Median: =MEDIAN(Revenue) → 386,76 € Minimum: =MIN(Revenue) → 41,17 € Maximum: =MAX(Revenue) → 46.616,00 € Spannweite (Bereich): =MAX(Revenue) - MIN(Revenue) → 46.574,83 € Standardabweichung: =STDEV(Revenue) → 3.963,94 € Quartil (Q1): =QUARTILE(Revenue, 1) → 131,40 € Quartil (Q3): =QUARTILE(Revenue, 3) → 994,38 € 3. Registerkarte: Pivot-Tabellen Vorgehensweise: Analyse der Teamleistung über zwei Pivot-Tabellen. Technik: Verwendung der „Summe von Revenue“ als Wertfeld. Auswertungen: Vertriebsmitarbeiter × Kategorie: Identifikation von Spezialisierungen der Mitarbeiter pro Produktlinie. Vertriebsmitarbeiter × Region: Analyse der regionalen Zuständigkeiten und Umsatzbeiträge. 4. Registerkarte: Top-Performer Vorgehensweise: Identifikation der Leistungsspitzen durch Sortier- und Filteransichten. Formeln & Technik: Anzahl der Geschäfte: =COUNTIF() pro Vertriebsmitarbeiter, sortiert absteigend. Durchschnittsvolumen: Berechnung über =AVERAGEIF() pro Mitarbeiter. Größte Transaktionen: Anwendung der Funktion =SORT() (bzw. Filtern), um die Top 10 der „Revenue“-Spalte zu isolieren. 5. Registerkarte: Diagramme Vorgehensweise: Visuelle Aufbereitung zur Beantwortung der Fragen von Diego Vargas. Methodik: Erstellung von fünf Diagrammtypen (Liniendiagramm, Säulendiagramm, Histogramm, Streudiagramm, Boxplot). Standards: Alle Diagramme verwenden präzise „Takeaway“-Titel, eine einheitliche Akzentfarbe (Blau) für den Fokus und eine konsequente Nullpunkt-Skalierung bei Balkendarstellungen. 6. Registerkarte: README (dieses Dokument) Zweck: Dokumentation des gesamten Arbeitsablaufs und der getroffenen Annahmen, um Nicht-Analysten die Interpretation der vorliegenden Zahlen und Analysen zu erleichtern.
